<?xml version="1.0"?>
<sdf version="1.6">
  <model name="diff_drive_robot">
    <!-- 로봇 본체 -->
    <link name="chassis">
      <pose>0 0 0.05 0 0 0</pose>
      <inertial>
        <mass>5.0</mass>
        <inertia>
          <ixx>0.0417</ixx>
          <iyy>0.0417</iyy>
          <izz>0.0833</izz>
          <ixy>0</ixy>
          <ixz>0</ixz>
          <iyz>0</iyz>
        </inertia>
      </inertial>
      <collision name="collision">
        <geometry>
          <box>
            <size>0.4 0.3 0.1</size>
          </box>
        </geometry>
      </collision>
      <visual name="visual">
        <geometry>
          <box>
            <size>0.4 0.3 0.1</size>
          </box>
        </geometry>
        <material>
          <ambient>0.2 0.2 0.8 1</ambient>
          <diffuse>0.2 0.2 0.8 1</diffuse>
          <specular>0.1 0.1 0.1 1</specular>
        </material>
      </visual>
    </link>

    <!-- 좌측 바퀴 -->
    <link name="left_wheel">
      <pose>0.1 0.175 0.05 -1.5707 0 0</pose>
      <inertial>
        <mass>1.0</mass>
        <inertia>
          <ixx>0.0029</ixx>
          <iyy>0.0029</iyy>
          <izz>0.0052</izz>
          <ixy>0</ixy>
          <ixz>0</ixz>
          <iyz>0</iyz>
        </inertia>
      </inertial>
      <collision name="collision">
        <geometry>
          <cylinder>
            <radius>0.05</radius>
            <length>0.04</length>
          </cylinder>
        </geometry>
      </collision>
      <visual name="visual">
        <geometry>
          <cylinder>
            <radius>0.05</radius>
            <length>0.04</length>
          </cylinder>
        </geometry>
        <material>
          <ambient>0.1 0.1 0.1 1</ambient>
          <diffuse>0.1 0.1 0.1 1</diffuse>
          <specular>0.1 0.1 0.1 1</specular>
        </material>
      </visual>
    </link>

    <!-- 우측 바퀴 -->
    <link name="right_wheel">
      <pose>0.1 -0.175 0.05 -1.5707 0 0</pose>
      <inertial>
        <mass>1.0</mass>
        <inertia>
          <ixx>0.0029</ixx>
          <iyy>0.0029</iyy>
          <izz>0.0052</izz>
          <ixy>0</ixy>
          <ixz>0</ixz>
          <iyz>0</iyz>
        </inertia>
      </inertial>
      <collision name="collision">
        <geometry>
          <cylinder>
            <radius>0.05</radius>
            <length>0.04</length>
          </cylinder>
        </geometry>
      </collision>
      <visual name="visual">
        <geometry>
          <cylinder>
            <radius>0.05</radius>
            <length>0.04</length>
          </cylinder>
        </geometry>
        <material>
          <ambient>0.1 0.1 0.1 1</ambient>
          <diffuse>0.1 0.1 0.1 1</diffuse>
          <specular>0.1 0.1 0.1 1</specular>
        </material>
      </visual>
    </link>

    <!-- 캐스터 휠 -->
    <link name="caster">
      <pose>-0.15 0 0.025 0 0 0</pose>
      <inertial>
        <mass>0.5</mass>
        <inertia>
          <ixx>0.0001</ixx>
          <iyy>0.0001</iyy>
          <izz>0.0001</izz>
          <ixy>0</ixy>
          <ixz>0</ixz>
          <iyz>0</iyz>
        </inertia>
      </inertial>
      <collision name="collision">
        <geometry>
          <sphere>
            <radius>0.025</radius>
          </sphere>
        </geometry>
        <surface>
          <friction>
            <ode>
              <mu>0.1</mu>
              <mu2>0.1</mu2>
            </ode>
          </friction>
        </surface>
      </collision>
      <visual name="visual">
        <geometry>
          <sphere>
            <radius>0.025</radius>
          </sphere>
        </geometry>
        <material>
          <ambient>0.3 0.3 0.3 1</ambient>
          <diffuse>0.3 0.3 0.3 1</diffuse>
          <specular>0.1 0.1 0.1 1</specular>
        </material>
      </visual>
    </link>

    <!-- 좌측 바퀴 조인트 -->
    <joint name="left_wheel_joint" type="revolute">
      <parent>chassis</parent>
      <child>left_wheel</child>
      <axis>
        <xyz>0 0 1</xyz>
        <limit>
          <lower>-1e+16</lower>
          <upper>1e+16</upper>
        </limit>
      </axis>
    </joint>

    <!-- 우측 바퀴 조인트 -->
    <joint name="right_wheel_joint" type="revolute">
      <parent>chassis</parent>
      <child>right_wheel</child>
      <axis>
        <xyz>0 0 1</xyz>
        <limit>
          <lower>-1e+16</lower>
          <upper>1e+16</upper>
        </limit>
      </axis>
    </joint>

    <!-- 캐스터 볼 조인트 -->
    <joint name="caster_joint" type="ball">
      <parent>chassis</parent>
      <child>caster</child>
    </joint>

    <!-- 차동 구동 플러그인 -->
    <plugin
      filename="ignition-gazebo-diff-drive-system"
      name="ignition::gazebo::systems::DiffDrive">
      <left_joint>left_wheel_joint</left_joint>
      <right_joint>right_wheel_joint</right_joint>
      <wheel_separation>0.35</wheel_separation>
      <wheel_radius>0.05</wheel_radius>
      <odom_publish_frequency>10</odom_publish_frequency>
      <topic>cmd_vel</topic>
    </plugin>
  </model>
</sdf> 